<?xml version="1.0" encoding="utf-8"?>
<!-- This URDF was automatically created by SolidWorks to URDF Exporter! Originally created by Stephen Brawner (brawner@gmail.com) 
     Commit Version: 1.6.0-4-g7f85cfe  Build Version: 1.6.7995.38578
     For more information, please see http://wiki.ros.org/sw_urdf_exporter -->
<robot
  name="Leader_arm_links.SLDASM">
  <link
    name="base_link">
    <inertial>
      <origin
        xyz="-0.02486 -3.8184E-07 0.032741"
        rpy="0 0 0" />
      <mass
        value="0.21832" />
      <!-- <inertia
        ixx="0.00015193"
        ixy="-5.2172E-07"
        ixz="2.1784E-05"
        iyy="0.00014266"
        iyz="-1.8991E-09"
        izz="0.00018377" /> -->
      <inertia 
        ixx="0.0001944" 
        ixy="0.0000005" 
        ixz="-0.0000065" 
        iyy="0.0002013" 
        iyz="-0.0000003" 
        izz="0.0002000" />
    </inertial>
    <visual>
      <origin
        xyz="0 0 0"
        rpy="0 0 0" />
      <geometry>
        <mesh
          filename="/home/yfx/lerobot_piper/lerobot/common/teleoperators/so102_leader/Leader_arm_links.SLDASM/meshes/base_link.STL" />
      </geometry>
      <material
        name="">
        <color
          rgba="0.75294 0.75294 0.75294 1" />
      </material>
    </visual>
    <collision>
      <origin
        xyz="0 0 0"
        rpy="0 0 0" />
      <geometry>
        <mesh
          filename="/home/yfx/lerobot_piper/lerobot/common/teleoperators/so102_leader/Leader_arm_links.SLDASM/meshes/base_link.STL" />
      </geometry>
    </collision>
  </link>
  <link
    name="link1">
    <inertial>
      <origin
        xyz="0.011134 -5.6E-05 0.017048"
        rpy="0 0 0" />
      <mass
        value="0.15375" />
      <!-- <inertia
        ixx="6.163E-05"
        ixy="-2.4039E-07"
        ixz="1.0411E-05"
        iyy="7.2865E-05"
        iyz="1.9626E-07"
        izz="3.8854E-05" /> -->
      <inertia 
        ixx="0.00014965" 
        ixy="0.00000016" 
        ixz=" -0.00005085" 
        iyy="0.00017708" 
        iyz="-0.00000013" 
        izz="0.00006492" />
    </inertial>
    <visual>
      <origin
        xyz="0 0 0"
        rpy="0 0 0" />
      <geometry>
        <mesh
          filename="/home/yfx/lerobot_piper/lerobot/common/teleoperators/so102_leader/Leader_arm_links.SLDASM/meshes/link1.STL" />
      </geometry>
      <material
        name="">
        <color
          rgba="0.75294 0.75294 0.75294 1" />
      </material>
    </visual>
    <collision>
      <origin
        xyz="0 0 0"
        rpy="0 0 0" />
      <geometry>
        <mesh
          filename="/home/yfx/lerobot_piper/lerobot/common/teleoperators/so102_leader/Leader_arm_links.SLDASM/meshes/link1.STL" />
      </geometry>
    </collision>
  </link>
  <joint
    name="joint1"
    type="revolute">
    <!-- <origin
      xyz="0.00057062 0 0.065387"
      rpy="5.7645E-05 0.0087265 0.0066058" /> -->
    <origin
      xyz="0 0 0"
      rpy="0 0 0" />
    <parent
      link="base_link" />
    <child
      link="link1" />
    <axis
      xyz="0 0 1" />
    <limit
      lower="-2.06"
      upper="2.06"
      effort="100"
      velocity="5" />
  </joint>
  <link
    name="link2">
    <inertial>
      <origin
        xyz="-0.0038502 0.1179 4.1361E-05"
        rpy="0 0 0" />
      <mass
        value="0.24721" />
      <!-- <inertia
        ixx="0.00061588"
        ixy="-3.1978E-06"
        ixz="-6.1517E-08"
        iyy="8.1694E-05"
        iyz="2.4945E-06"
        izz="0.00056895" /> -->
      <inertia 
        ixx="0.00103532" 
        ixy="-0.00006398" 
        ixz="0.00000023" 
        iyy="0.00009955" 
        iyz="-0.00000182" 
        izz="0.00099653" />
    </inertial>
    <visual>
      <origin
        xyz="0 0 0"
        rpy="0 0 0" />
      <geometry>
        <mesh
          filename="/home/yfx/lerobot_piper/lerobot/common/teleoperators/so102_leader/Leader_arm_links.SLDASM/meshes/link2.STL" />
      </geometry>
      <material
        name="">
        <color
          rgba="0.75294 0.75294 0.75294 1" />
      </material>
    </visual>
    <collision>
      <origin
        xyz="0 0 0"
        rpy="0 0 0" />
      <geometry>
        <mesh
          filename="/home/yfx/lerobot_piper/lerobot/common/teleoperators/so102_leader/Leader_arm_links.SLDASM/meshes/link2.STL" />
      </geometry>
    </collision>
  </link>
  <joint
    name="joint2"
    type="revolute">
    <!-- <origin
      xyz="9.9432E-05 -0.00048779 0.054336"
      rpy="1.5795 0 3.1416" /> -->
    <origin
      xyz="0 0 0.054"
      rpy="-1.5795 0 3.1416" />
    <parent
      link="link1" />
    <child
      link="link2" />
    <axis
      xyz="0 0 1" />
    <limit
      lower="-1.84"
      upper="1.84"
      effort="100"
      velocity="5" />
  </joint>
  <link
    name="link3">
    <inertial>
      <origin
        xyz="0.066039 -0.00011194 0.0083372"
        rpy="0 0 0" />
      <mass
        value="0.14677" />
      <inertia
        ixx="5.6096E-05"
        ixy="3.1134E-07"
        ixz="-3.0937E-06"
        iyy="0.00010888"
        iyz="-5.7791E-08"
        izz="6.9058E-05" />
    </inertial>
    <visual>
      <origin
        xyz="0 0 0"
        rpy="0 0 0" />
      <geometry>
        <mesh
          filename="/home/yfx/lerobot_piper/lerobot/common/teleoperators/so102_leader/Leader_arm_links.SLDASM/meshes/link3.STL" />
      </geometry>
      <material
        name="">
        <color
          rgba="0.75294 0.75294 0.75294 1" />
      </material>
    </visual>
    <collision>
      <origin
        xyz="0 0 0"
        rpy="0 0 0" />
      <geometry>
        <mesh
          filename="/home/yfx/lerobot_piper/lerobot/common/teleoperators/so102_leader/Leader_arm_links.SLDASM/meshes/link3.STL" />
      </geometry>
    </collision>
  </link>
  <joint
    name="joint3"
    type="revolute">
    <origin
      xyz="-0.028 0.18386 -0.0006"
      rpy="0 0 3.1416" />
    <parent
      link="link2" />
    <child
      link="link3" />
    <axis
      xyz="0 0 1" />
    <limit
      lower="-1.84"
      upper="1.84"
      effort="100"
      velocity="5" />
  </joint>
  <link
    name="link4">
    <inertial>
      <origin
        xyz="0.00092941 0.0014138 0.036212"
        rpy="0 0 0" />
      <mass
        value="0.11324" />
      <inertia
        ixx="2.1147E-05"
        ixy="5.372E-08"
        ixz="-2.0875E-07"
        iyy="2.5875E-05"
        iyz="-8.5152E-07"
        izz="1.9766E-05" />
    </inertial>
    <visual>
      <origin
        xyz="0 0 0"
        rpy="0 0 0" />
      <geometry>
        <mesh
          filename="/home/yfx/lerobot_piper/lerobot/common/teleoperators/so102_leader/Leader_arm_links.SLDASM/meshes/link4.STL" />
      </geometry>
      <material
        name="">
        <color
          rgba="0.75294 0.75294 0.75294 1" />
      </material>
    </visual>
    <collision>
      <origin
        xyz="0 0 0"
        rpy="0 0 0" />
      <geometry>
        <mesh
          filename="/home/yfx/lerobot_piper/lerobot/common/teleoperators/so102_leader/Leader_arm_links.SLDASM/meshes/link4.STL" />
      </geometry>
    </collision>
  </link>
  <joint
    name="joint4"
    type="revolute">
    <origin
      xyz="0.10556 0 0.0011"
      rpy="0 1.5708 0" />
    <parent
      link="link3" />
    <child
      link="link4" />
    <axis
      xyz="0 0 -1" />
    <limit
      lower="-1.745"
      upper="1.745"
      effort="100"
      velocity="5" />
  </joint>
  <link
    name="link5">
    <inertial>
      <origin
        xyz="0.037546 -0.00022674 0.0097089"
        rpy="0 0 0" />
      <mass
        value="0.10193" />
      <inertia
        ixx="2.9356E-05"
        ixy="1.2027E-07"
        ixz="-1.9443E-06"
        iyy="3.5834E-05"
        iyz="2.1004E-08"
        izz="1.8483E-05" />
    </inertial>
    <visual>
      <origin
        xyz="0 0 0"
        rpy="0 0 0" />
      <geometry>
        <mesh
          filename="/home/yfx/lerobot_piper/lerobot/common/teleoperators/so102_leader/Leader_arm_links.SLDASM/meshes/link5.STL" />
      </geometry>
      <material
        name="">
        <color
          rgba="0.75294 0.75294 0.75294 1" />
      </material>
    </visual>
    <collision>
      <origin
        xyz="0 0 0"
        rpy="0 0 0" />
      <geometry>
        <mesh
          filename="/home/yfx/lerobot_piper/lerobot/common/teleoperators/so102_leader/Leader_arm_links.SLDASM/meshes/link5.STL" />
      </geometry>
    </collision>
  </link>
  <joint
    name="joint5"
    type="revolute">
    <origin
      xyz="0.0016 -0.0001 0.0592"
      rpy="3.1416 -1.5708 0" />
    <parent
      link="link4" />
    <child
      link="link5" />
    <axis
      xyz="0 0 1" />
    <limit
      lower="-1.22"
      upper="1.22"
      effort="100"
      velocity="5" />
  </joint>
  <link
    name="link6">
    <inertial>
      <origin
        xyz="-0.0008388 0.016643 0.039907"
        rpy="0 0 0" />
      <mass
        value="0.19204" />
      <inertia
        ixx="8.0488E-05"
        ixy="-4.6544E-07"
        ixz="-1.2739E-06"
        iyy="3.6704E-05"
        iyz="-1.7086E-05"
        izz="6.9842E-05" />
    </inertial>
    <visual>
      <origin
        xyz="0 0 0"
        rpy="0 0 0" />
      <geometry>
        <mesh
          filename="/home/yfx/lerobot_piper/lerobot/common/teleoperators/so102_leader/Leader_arm_links.SLDASM/meshes/link6.STL" />
      </geometry>
      <material
        name="">
        <color
          rgba="0.75294 0.75294 0.75294 1" />
      </material>
    </visual>
    <collision>
      <origin
        xyz="0 0 0"
        rpy="0 0 0" />
      <geometry>
        <mesh
          filename="/home/yfx/lerobot_piper/lerobot/common/teleoperators/so102_leader/Leader_arm_links.SLDASM/meshes/link6.STL" />
      </geometry>
    </collision>
  </link>
  <joint
    name="joint6"
    type="revolute">
    <origin
      xyz="0.0615000000000013 0 0"
      rpy="-1.57147897231993 1.57079631189374 -1.57360275146589" />
    <parent
      link="link5" />
    <child
      link="link6" />
    <axis
      xyz="0 0 1" />
    <limit
      lower="-2.0944"
      upper="2.0944"
      effort="100"
      velocity="3" />
  </joint>
</robot>